<robot name="finger2">

	<!-- LINKS -->
	
 	<link name="finger2_1">
		<visual>
		    <origin xyz="0 0 0.025" rpy="0 0 0"/>
			<geometry>
				<box size="0.02 0.02 0.05"/>
			</geometry>
			<material name="Cyan1">
	       		<color rgba="0 0.9 0.9 1.0"/>
	     	</material>
		</visual>	
	</link>
	
	<link name="finger2_2">
		<visual>
		    <origin xyz="0 0 0.015" rpy="0 0 0"/>
			<geometry>
				<box size="0.02 0.02 0.03"/>
			</geometry>
			<material name="Cyan1">
	       		<color rgba="0 0.9 0.9 1.0"/>
	     	</material>
		</visual>	
	</link>
	
	<link name="finger2_3">
		<visual>
		    <origin xyz="0 0 0.01" rpy="0 0 0"/>
			<geometry>
				<box size="0.02 0.02 0.02"/>
			</geometry>
			<material name="Cyan1">
	       		<color rgba="0 0.9 0.9 1.0"/>
	     	</material>
		</visual>	
	</link>
	
	<!-- JOINTS -->

	<joint name="finger2_1_finger2_2_joint" type="revolute">
    	<parent link="finger2_1"/>
    	<child link="finger2_2"/>
    	<origin xyz="0 0 0.05" rpy="0 0 0"/>
    	<axis xyz="0 1 0"/>
    	<limit lower="-3.1416" upper="3.1416" effort="10" velocity="3"/>
  	</joint>
	
	<joint name="finger1_2_finger1_3_joint" type="revolute">
    	<parent link="finger2_2"/>
    	<child link="finger2_3"/>
    	<origin xyz="0 0 0.03" rpy="0 0 0"/>
    	<axis xyz="0 1 0"/>
    	<limit lower="-3.1416" upper="3.1416" effort="10" velocity="3"/>
  	</joint>


</robot>