<robot name="finger3">

	<!-- LINKS -->
	
 	<link name="finger3_1">
		<visual>
		    <origin xyz="0 0 0.0225" rpy="0 0 0"/>
			<geometry>
				<box size="0.02 0.02 0.045"/>
			</geometry>
			<material name="Cyan1">
	       		<color rgba="0 0.9 0.9 1.0"/>
	     	</material>
		</visual>	
	</link>
	
	<link name="finger3_2">
		<visual>
		    <origin xyz="0 0 0.0125" rpy="0 0 0"/>
			<geometry>
				<box size="0.02 0.02 0.025"/>
			</geometry>
			<material name="Cyan1">
	       		<color rgba="0 0.9 0.9 1.0"/>
	     	</material>
		</visual>	
	</link>
	
	<link name="finger3_3">
		<visual>
		    <origin xyz="0 0 0.01" rpy="0 0 0"/>
			<geometry>
				<box size="0.02 0.02 0.02"/>
			</geometry>
			<material name="Cyan1">
	       		<color rgba="0 0.9 0.9 1.0"/>
	     	</material>
		</visual>	
	</link>
	
	<!-- JOINTS -->

	<joint name="finger3_1_finger2_2_joint" type="revolute">
    	<parent link="finger3_1"/>
    	<child link="finger3_2"/>
    	<origin xyz="0 0 0.045" rpy="0 0 0"/>
    	<axis xyz="0 1 0"/>
    	<limit lower="-3.1416" upper="3.1416" effort="10" velocity="3"/>
  	</joint>
	
	<joint name="finger3_2_finger2_3_joint" type="revolute">
    	<parent link="finger3_2"/>
    	<child link="finger3_3"/>
    	<origin xyz="0 0 0.02" rpy="0 0 0"/>
    	<axis xyz="0 1 0"/>
    	<limit lower="-3.1416" upper="3.1416" effort="10" velocity="3"/>
  	</joint>


</robot>